
> @fxts/core@1.11.0 test
> jest

FAIL test/Lazy/map.spec.ts
  ● map › sync › should throw an error when the callback is asynchronous

    expect(received).toThrowError(expected)

    Expected message: "'Iterable' can not used with async function.
    If you want to deal with async function, see: [toAsync](https://fxts.dev/docs/toAsync)"

    Received function did not throw

      19 |     it("should throw an error when the callback is asynchronous", function () {
      20 |       const res = () => [...map(add10Async, [1, 2, 3, 4, 5])];
    > 21 |       expect(res).toThrowError(new AsyncFunctionException());
         |                   ^
      22 |     });
      23 |
      24 |     it("should be able to be used as a curried function in the pipeline", function () {

      at Object.<anonymous> (test/Lazy/map.spec.ts:21:19)


Test Suites: 1 failed, 104 passed, 105 total
Tests:       1 failed, 867 passed, 868 total
Snapshots:   0 total
Time:        20.509 s, estimated 24 s
